[2022-11-30T22:50:41.186+0000] {taskinstance.py:1165} INFO - Dependencies all met for <TaskInstance: twitter_etl.load scheduled__2022-11-30T22:45:35.765224+00:00 [queued]>
[2022-11-30T22:50:41.195+0000] {taskinstance.py:1165} INFO - Dependencies all met for <TaskInstance: twitter_etl.load scheduled__2022-11-30T22:45:35.765224+00:00 [queued]>
[2022-11-30T22:50:41.196+0000] {taskinstance.py:1362} INFO - 
--------------------------------------------------------------------------------
[2022-11-30T22:50:41.196+0000] {taskinstance.py:1363} INFO - Starting attempt 1 of 2
[2022-11-30T22:50:41.196+0000] {taskinstance.py:1364} INFO - 
--------------------------------------------------------------------------------
[2022-11-30T22:50:41.210+0000] {taskinstance.py:1383} INFO - Executing <Task(BashOperator): load> on 2022-11-30 22:45:35.765224+00:00
[2022-11-30T22:50:41.214+0000] {standard_task_runner.py:55} INFO - Started process 6743 to run task
[2022-11-30T22:50:41.216+0000] {standard_task_runner.py:82} INFO - Running: ['***', 'tasks', 'run', 'twitter_etl', 'load', 'scheduled__2022-11-30T22:45:35.765224+00:00', '--job-id', '602', '--raw', '--subdir', 'DAGS_FOLDER/twitter_dags.py', '--cfg-path', '/tmp/tmpxohsjiu7']
[2022-11-30T22:50:41.218+0000] {standard_task_runner.py:83} INFO - Job 602: Subtask load
[2022-11-30T22:50:41.271+0000] {task_command.py:376} INFO - Running <TaskInstance: twitter_etl.load scheduled__2022-11-30T22:45:35.765224+00:00 [running]> on host e7b2a4ab9b7f
[2022-11-30T22:50:41.330+0000] {taskinstance.py:1590} INFO - Exporting the following env vars:
AIRFLOW_CTX_DAG_EMAIL=lambobr1994@gmail.com
AIRFLOW_CTX_DAG_OWNER=***
AIRFLOW_CTX_DAG_ID=twitter_etl
AIRFLOW_CTX_TASK_ID=load
AIRFLOW_CTX_EXECUTION_DATE=2022-11-30T22:45:35.765224+00:00
AIRFLOW_CTX_TRY_NUMBER=1
AIRFLOW_CTX_DAG_RUN_ID=scheduled__2022-11-30T22:45:35.765224+00:00
[2022-11-30T22:50:41.331+0000] {subprocess.py:63} INFO - Tmp dir root location: 
 /tmp
[2022-11-30T22:50:41.331+0000] {subprocess.py:75} INFO - Running command: ['/bin/bash', '-c', 'python3 /opt/***/python_scripts/load.py']
[2022-11-30T22:50:41.339+0000] {subprocess.py:86} INFO - Output:
[2022-11-30T22:50:44.020+0000] {subprocess.py:93} INFO - Traceback (most recent call last):
[2022-11-30T22:50:44.020+0000] {subprocess.py:93} INFO -   File "/opt/***/python_scripts/load.py", line 101, in <module>
[2022-11-30T22:50:44.020+0000] {subprocess.py:93} INFO -     load_data_to_cloud_storage(filename=FILENAME, project=PROJECT, bucket=BUCKET, utc=UTC_DATETIME)
[2022-11-30T22:50:44.020+0000] {subprocess.py:93} INFO -   File "/opt/***/python_scripts/load.py", line 22, in load_data_to_cloud_storage
[2022-11-30T22:50:44.021+0000] {subprocess.py:93} INFO -     storage_client = storage.Client(project=project)    #project name in GCP
[2022-11-30T22:50:44.021+0000] {subprocess.py:93} INFO -   File "/home/***/.local/lib/python3.10/site-packages/google/cloud/storage/client.py", line 161, in __init__
[2022-11-30T22:50:44.021+0000] {subprocess.py:93} INFO -     super(Client, self).__init__(
[2022-11-30T22:50:44.021+0000] {subprocess.py:93} INFO -   File "/home/***/.local/lib/python3.10/site-packages/google/cloud/client/__init__.py", line 321, in __init__
[2022-11-30T22:50:44.021+0000] {subprocess.py:93} INFO -     Client.__init__(
[2022-11-30T22:50:44.021+0000] {subprocess.py:93} INFO -   File "/home/***/.local/lib/python3.10/site-packages/google/cloud/client/__init__.py", line 178, in __init__
[2022-11-30T22:50:44.021+0000] {subprocess.py:93} INFO -     credentials, _ = google.auth.default(scopes=scopes)
[2022-11-30T22:50:44.022+0000] {subprocess.py:93} INFO -   File "/home/***/.local/lib/python3.10/site-packages/google/auth/_default.py", line 646, in default
[2022-11-30T22:50:44.022+0000] {subprocess.py:93} INFO -     raise exceptions.DefaultCredentialsError(_HELP_MESSAGE)
[2022-11-30T22:50:44.022+0000] {subprocess.py:93} INFO - google.auth.exceptions.DefaultCredentialsError: Could not automatically determine credentials. Please set GOOGLE_APPLICATION_CREDENTIALS or explicitly create credentials and re-run the application. For more information, please see https://cloud.google.com/docs/authentication/getting-started
[2022-11-30T22:50:44.223+0000] {subprocess.py:97} INFO - Command exited with return code 1
[2022-11-30T22:50:44.233+0000] {taskinstance.py:1851} ERROR - Task failed with exception
Traceback (most recent call last):
  File "/home/airflow/.local/lib/python3.10/site-packages/airflow/operators/bash.py", line 196, in execute
    raise AirflowException(
airflow.exceptions.AirflowException: Bash command failed. The command returned a non-zero exit code 1.
[2022-11-30T22:50:44.237+0000] {taskinstance.py:1401} INFO - Marking task as UP_FOR_RETRY. dag_id=twitter_etl, task_id=load, execution_date=20221130T224535, start_date=20221130T225041, end_date=20221130T225044
[2022-11-30T22:50:44.254+0000] {standard_task_runner.py:100} ERROR - Failed to execute job 602 for task load (Bash command failed. The command returned a non-zero exit code 1.; 6743)
[2022-11-30T22:50:44.278+0000] {local_task_job.py:159} INFO - Task exited with return code 1
[2022-11-30T22:50:44.298+0000] {taskinstance.py:2623} INFO - 0 downstream tasks scheduled from follow-on schedule check
